Workbook
Name INPUT: 'Sproat Escapement Data '!$A$28:$M$29
Name INPUT: 'STAMP Escapement Data'!$A$28:$M$601

Sheet STAMP Escapement Data
A1: Historic Stamp Falls Daily Counts from Reports 1986 to 2003.
A3: Year | B3: Data Source | C3: Data Type
A4: 1986
A5: 1987
A6: 1988
A7: 1989
A8: 1990 | B8: Bocking. 1991 | C8: Adjusted for observer error and periods of non-observation
A9: 1991 | B9: Bocking & Nass. 1992 | C9: Adjusted for observer error and periods of non-observation
A10: 1992 | B10: Nelson. 1993 | C10: Adjusted for observer error and periods of non-observation
A11: 1993 | B11: Nelson. 1994 | C11: Chinook Coho and Sockeye are adjusted for observer error and periods of non-observation
A12: 1994 | B12: Nelson. 1995 | C12: Chinook Coho and Sockeye are adjusted for observer error and periods of non-observation
A13: 1995
A14: 1996
A15: 1997
A16: 1998
A17: 1999
A18: 2000
A19: 2001
A20: 2002 | B20: Stamp Falls Database. | C20: Raw counts. Not adjusted.
A22: 1998 and 2001 included totals from GCL Dam counter, I deleted this so we don't double count. Dawn
A29: DATE | B29: STDATE | C29: YEAR | D29: CO | E29: JCO | F29: PK | G29: CM | H29: CN | I29: JCN | J29: ST | K29: SX | L29: JSX | M29: UNK | N29: COMMENT | O29: River Temp (AM) oC | P29: River height (m) | Q29: weather
A30: 31673 | B30: =CONCATENATE(TEXT(A30,"mm"),TEXT(A30,"dd")) -> 0918 | C30: 1986 | D30: 35 | H30: 94 | J30: 5 | K30: 149 | M30: 183
A31: 31674 | B31: =CONCATENATE(TEXT(A31,"mm"),TEXT(A31,"dd")) -> 0919 | C31: 1986 | D31: 448 | H31: 197 | J31: 13 | K31: 342 | M31: 799
A32: 31675 | B32: =CONCATENATE(TEXT(A32,"mm"),TEXT(A32,"dd")) -> 0920 | C32: 1986 | D32: 7 | H32: 438 | J32: 34 | K32: 457 | M32: 54
A33: 31676 | B33: =CONCATENATE(TEXT(A33,"mm"),TEXT(A33,"dd")) -> 0921 | C33: 1986 | D33: 836 | H33: 634 | J33: 26 | K33: 1469 | M33: 1339
A34: 31677 | B34: =CONCATENATE(TEXT(A34,"mm"),TEXT(A34,"dd")) -> 0922 | C34: 1986 | D34: 2103 | H34: 1336 | J34: 22 | K34: 4947 | M34: 1888
A35: 31678 | B35: =CONCATENATE(TEXT(A35,"mm"),TEXT(A35,"dd")) -> 0923 | C35: 1986 | D35: 504 | H35: 1307 | J35: 12 | K35: 3979 | M35: 977
A36: 31679 | B36: =CONCATENATE(TEXT(A36,"mm"),TEXT(A36,"dd")) -> 0924 | C36: 1986 | D36: 188 | H36: 298 | J36: 0 | K36: 1282 | M36: 489
A37: 31680 | B37: =CONCATENATE(TEXT(A37,"mm"),TEXT(A37,"dd")) -> 0925 | C37: 1986 | D37: 1273 | H37: 568 | J37: 20 | K37: 3000 | M37: 285
A38: 31681 | B38: =CONCATENATE(TEXT(A38,"mm"),TEXT(A38,"dd")) -> 0926 | C38: 1986 | D38: 1033 | H38: 493 | J38: 6 | K38: 2137 | M38: 140
A39: 31682 | B39: =CONCATENATE(TEXT(A39,"mm"),TEXT(A39,"dd")) -> 0927 | C39: 1986 | D39: 12 | H39: 86 | J39: 0 | K39: 285 | M39: 28
A40: 31683 | B40: =CONCATENATE(TEXT(A40,"mm"),TEXT(A40,"dd")) -> 0928 | C40: 1986 | D40: 302 | H40: 272 | J40: 3 | K40: 1501 | M40: 1577
A41: 31684 | B41: =CONCATENATE(TEXT(A41,"mm"),TEXT(A41,"dd")) -> 0929 | C41: 1986 | D41: 1442 | H41: 677 | J41: 3 | K41: 1014 | M41: 559
... A135: 32100 | B135: =CONCATENATE(TEXT(A135,"mm"),TEXT(A135,"dd")) -> 1119 | C135: 1987 | D135: 0 | H135: 0 | J135: 2 | K135: 3 | M135: 0
A136: =DATE(88,9,15) -> 32401 | B136: =CONCATENATE(TEXT(A136,"mm"),TEXT(A136,"dd")) -> 0915 | C136: 1988 | D136: 25 | E136: 0 | H136: 684 | I136: 20 | J136: 1 | K136: 44 | M136: 10 | N136: STARTED AT 1230 HRS.
A137: =DATE(88,9,16) -> 32402 | B137: =CONCATENATE(TEXT(A137,"mm"),TEXT(A137,"dd")) -> 0916 | C137: 1988 | D137: 53 | E137: 23 | H137: 1574 | I137: 241 | J137: 4 | K137: 189 | M137: 119
A138: =DATE(88,9,17) -> 32403 | B138: =CONCATENATE(TEXT(A138,"mm"),TEXT(A138,"dd")) -> 0917 | C138: 1988 | D138: 431 | E138: 77 | H138: 1789 | I138: 414 | J138: 9 | K138: 242 | M138: 156
A139: =DATE(88,9,18) -> 32404 | B139: =CONCATENATE(TEXT(A139,"mm"),TEXT(A139,"dd")) -> 0918 | C139: 1988 | D139: 582 | E139: 160 | H139: 1165 | I139: 157 | J139: 1 | K139: 171 | M139: 52
A140: =DATE(88,9,19) -> 32405 | B140: =CONCATENATE(TEXT(A140,"mm"),TEXT(A140,"dd")) -> 0919 | C140: 1988 | D140: 682 | E140: 216 | H140: 1864 | I140: 533 | J140: 2 | K140: 485 | M140: 105
A141: =DATE(88,9,20) -> 32406 | B141: =CONCATENATE(TEXT(A141,"mm"),TEXT(A141,"dd")) -> 0920 | C141: 1988 | D141: 952 | E141: 58 | H141: 1554 | I141: 617 | J141: 5 | K141: 653 | M141: 65 | N141: FISHWAY CLOSED FROM 1010 TO 1200 HRS.
...

Sheet Sproat Escapement Data 
A1: Historic Stamp Falls Daily Counts from Reports 1986 to 2003.
A3: Year | B3: Data Source | C3: Data Type
A4: 1986
A5: 1987
A6: 1988
A7: 1989
A8: 1990 | B8: Bocking. 1991 | C8: Adjusted for observer error and periods of non-observation
A9: 1991 | B9: Bocking & Nass. 1992 | C9: Adjusted for observer error and periods of non-observation
A10: 1992 | B10: Nelson. 1993 | C10: Adjusted for observer error and periods of non-observation
A11: 1993 | B11: Nelson. 1994 | C11: Chinook Coho and Sockeye are adjusted for observer error and periods of non-observation
A12: 1994 | B12: Nelson. 1995 | C12: Chinook Coho and Sockeye are adjusted for observer error and periods of non-observation
A13: 1995
A14: 1996
A15: 1997
A16: 1998
A17: 1999
A18: 2000
A19: 2001
A20: 2002 | B20: Stamp Falls Database. | C20: Raw counts. Not adjusted.
A22: 1998 and 2001 included totals from GCL Dam counter, I deleted this so we don't double count. Dawn
A29: DATE | B29: STDATE | C29: YEAR | D29: CO | E29: JCO | F29: PK | G29: CM | H29: CN | I29: JCN | J29: ST | K29: SX | L29: JSX | M29: UNK | N29: COMMENT | O29: River Temp (AM) oC | P29: River height (m) | Q29: weather
A30: 41486 | B30: 731 | C30: 2013 | D30: 0 | E30: 0 | G30: 0 | H30: 3 | J30: 124 | K30: 189162 | L30: 227473 | N30: Totals to date (up to July 31)
A31: 41487 | B31: 801 | C31: 2013 | D31: 0 | E31: 0 | G31: 0 | H31: 0 | J31: 0 | K31: 415.9476 | L31: 4153.4037 | N31: Sockeye counts are only in-season visual estimates. True final counts will be generated by applying weekly biodata to total sockeye counts.
A32: 41488 | B32: 802 | C32: 2013 | D32: 0 | E32: 0 | G32: 0 | H32: 0 | J32: 0 | K32: 713.58734 | L32: 1566.054 | N32: Sockeye counts are only in-season visual estimates. True final counts will be generated by applying weekly biodata to total sockeye counts.
A33: 41489 | B33: 803 | C33: 2013 | D33: 3 | E33: 0 | G33: 0 | H33: 0 | J33: 0 | K33: 154.22787 | L33: 341.72058 | N33: Sockeye counts are only in-season visual estimates. True final counts will be generated by applying weekly biodata to total sockeye counts.
A34: 41490 | B34: 804 | C34: 2013 | D34: 0 | E34: 0 | G34: 0 | H34: 0 | J34: 9 | K34: 1629.7507 | L34: 1035.1935 | N34: Sockeye counts are only in-season visual estimates. True final counts will be generated by applying weekly biodata to total sockeye counts.
A35: 41491 | B35: 805 | C35: 2013 | D35: 3 | E35: 0 | G35: 0 | H35: 0 | J35: 0 | K35: 218.37275 | L35: 960.84011 | N35: Sockeye counts are only in-season visual estimates. True final counts will be generated by applying weekly biodata to total sockeye counts.
A36: 41492 | B36: 806 | C36: 2013 | D36: 12 | E36: 3 | G36: 0 | H36: 0 | J36: 3 | K36: 348.6982 | L36: 3342.6931 | N36: Sockeye counts are only in-season visual estimates. True final counts will be generated by applying weekly biodata to total sockeye counts.
A37: 41493 | B37: 807 | C37: 2013 | D37: 0 | E37: 0 | G37: 0 | H37: 0 | J37: 0 | K37: 183 | L37: 1200 | N37: Sockeye counts are only in-season visual estimates. True final counts will be generated by applying weekly biodata to total sockeye counts.
A38: 41494 | B38: 808 | C38: 2013 | D38: 0 | E38: 0 | G38: 0 | H38: 0 | J38: 0 | K38: 33 | L38: 69 | N38: Sockeye counts are only in-season visual estimates. True final counts will be generated by applying weekly biodata to total sockeye counts.
A39: 41495 | B39: 809 | C39: 2013 | D39: 0 | E39: 0 | G39: 0 | H39: 0 | J39: 0 | K39: 18 | L39: 39 | N39: Sockeye counts are only in-season visual estimates. True final counts will be generated by applying weekly biodata to total sockeye counts.
A40: 41496 | B40: 810 | C40: 2013 | D40: 0 | E40: 0 | G40: 0 | H40: 0 | J40: 0 | K40: 110.60182 | L40: 109.0197 | N40: Sockeye counts are only in-season visual estimates. True final counts will be generated by applying weekly biodata to total sockeye counts.
A41: 41497 | B41: 811 | C41: 2013 | D41: 0 | E41: 0 | G41: 0 | H41: 0 | J41: 0 | K41: 588.03 | L41: 3568.8152 | N41: Sockeye counts are only in-season visual estimates. True final counts will be generated by applying weekly biodata to total sockeye counts.
... A129: 41585 | B129: 1107 | C129: 2013 | D129: 11.37931 | E129: 2.0689655 | G129: 0 | H129: 1 | J129: 0 | K129: 39 | L129: 0 | N129: Sockeye counts are only in-season visual estimates. True final counts will be generated by applying weekly biodata to total sockeye counts.
A130: 41586 | B130: 1108 | C130: 2013
A131: 41587 | B131: 1109 | C131: 2013
A132: 41588 | B132: 1110 | C132: 2013
A133: 41589 | B133: 1111 | C133: 2013
A134: 41590 | B134: 1112 | C134: 2013
A135: 41591 | B135: 1113 | C135: 2013
...

Sheet  STAMP Summary
A1: STAMP FALLS COUNTS | J1: (actual counts unadjusted for verification or flooding) | U1: STAMP FALLS CHINOOK
A2: NB. All data in black requires some input. All dark blue data is calculated (but comments may need editing). | J2: 2000-2011. Counts from daylight hours. Night counts not included.
J3: 2012 onwards. Counts include both daytime and nighttime counts. | U3: ESCAPEMENTS, 2002-2014 | CL3: Jack Chinook
B4: copy new data to w:\chinook\termrbt\stamp falls | BK4: Expected Total Escapement
A5: YEAR | B5: (All) | BJ5: 21000 | BK5: 21000 | CL5: working pivot table for interest only.
B7: Data | M7: Sum of CN | N7: YEAR | CK7: Sum of JCN | CL7: YEAR | DE7: CUMULATIVE ESCAPEMENTS OF CHINOOK JACKS
A8: STDATE | B8: Adult chinook | C8: Jack Chinook | D8: Adult Coho | E8: Jack Coho | F8: Adult Sockeye | G8: Jack Sockeye | H8: Steelhead | I8: Chum | J8: Pink | M8: STDATE | N8: 2022 | O8: 2021 | P8: 2020 | Q8: 2019 | R8: 2018 | S8: 2017 | T8: 2016 | U8: 2015 | V8: 2014 | W8: 2013 | X8: 2012 | Y8: 2011 | Z8: 2010 | AA8: 2009 | AB8: 2008 | AC8: 2007 | AD8: 2006 | AE8: 2005 | AF8: 2004 | AG8: 2003 | AH8: 2002 | AI8: 2001 | AK8: 2022 | AL8: 2021 | AM8: 2020 | AN8: 2019 | AO8: 2018 | AP8: 2017 | AQ8: 2016 | AR8: 2015 | AS8: 2014 | AT8: 2013 | AU8: 2012 | AV8: 2011 | AW8: 2010 | AX8: 2009 | AY8: 2008 | AZ8: 2007 | BA8: 2006 | BB8: 2005 | BC8: 2004 | BD8: 2003 | BE8: 2002 | BF8: 2001 | BI8: 2022 | BJ8: 2021 | BK8: 2020 | BL8: 2019 | BM8: 2018 | BN8: 2017 | BO8: 2016 | BP8: 2015 | BQ8: 2014 | BR8: 2013 | BS8: 2012 | BT8: 2011 | BU8: 2010 | BV8: 2009 | BW8: 2008 | BX8: 2007 | BY8: 2006 | BZ8: 2005 | CA8: 2004 | CB8: 2003 | CC8: 2002 | CD8: 2001 | CK8: STDATE | CL8: 2019 | CM8: 2018 | CN8: 2017 | CO8: 2016 | CP8: 2015 | CQ8: 2014 | CR8: 2013 | CS8: 2012 | CT8: 2011 | CU8: 2010 | CV8: 2009 | CW8: 2008 | CX8: 2007 | CY8: 2006 | CZ8: 2005 | DA8: 2004 | DB8: 2003 | DC8: 2002 | DE8: Date | DF8: 2019 | DG8: 2018 | DH8: 2017 | DI8: 2016 | DJ8: 2015 | DK8: 2014 | DL8: 2013 | DM8: 2012 | DN8: 2011 | DO8: 2010 | DP8: 2009 | DQ8: 2008 | DR8: 2007 | DS8: 2006
A9: 0731 | B9: 108 | C9: 0 | D9: 81 | E9: 6 | F9: 299621 | G9: 125776 | H9: 817.5 | I9: 0 | J9: 1 | M9: 0731 | N9: 67 | O9: 55 | P9: 33 | Q9: 43 | R9: 12 | S9: 29 | T9: 6.5 | U9: 0 | V9: 1 | W9: 0 | X9: 0 | Y9: 0 | Z9: 0 | AA9: 0 | AB9: 0 | AC9: 0 | AD9: 0 | AE9: 0 | AF9: 0 | AG9: 0 | AH9: 0 | AI9: 0 | AK9: =N9 -> 67 | AL9: =O9 -> 55 | AM9: =P9 -> 33 | AN9: =Q9 -> 43 | AO9: =R9 -> 12 | AP9: =S9 -> 29 | AQ9: =T9 -> 6.5 | AR9: =U9 -> 0 | ... BF9: =AI9 -> 0 | BI9: =AK9/BJ$5 -> 0.0031904762 | BJ9: =IF(AL9/$BK$5>1,1,AL9/$BK$5) -> 0.0026190476 | BK9: =IF(AM9/$BK$5>1,1,AM9/$BK$5) -> 0.0015714286 | BL9: =IF(AN9/$BK$5>1,1,AN9/$BK$5) -> 0.002047619 | BM9: =IF(AO9/$BK$5>1,1,AO9/$BK$5) -> 0.00057142857 | BN9: =IF(AP9/$BK$5>1,1,AP9/$BK$5) -> 0.0013809524 | BO9: =IF(AQ9/$BK$5>1,1,AQ9/$BK$5) -> 0.00030952381 | BP9: =IF(AR9/$BK$5>1,1,AR9/$BK$5) -> 0 | BQ9: =IF(AS9/$BK$5>1,1,AS9/$BK$5) -> 4.7619048e-05 | ... CD9: =IF(BF9/$BK$5>1,1,BF9/$BK$5) -> 0 | CK9: 0731 | CL9: 0 | CM9: 0 | CN9: 2 | CO9: 0 | CP9: 0 | CQ9: 6 | CR9: 0 | CS9: 0 | CT9: 0 | CU9: 0 | CV9: 0 | CW9: 0 | CX9: 0 | CY9: 0 | CZ9: 0 | DA9: 0 | DB9: 0 | DC9: 0 | DE9: 41851 | DF9: =CL9 -> 0 | DG9: =CM9 -> 0 | DH9: =CN9 -> 2 | DI9: =CO9 -> 0 | DJ9: =CP9 -> 0 | DK9: =CQ9 -> 6 | DL9: =CR9 -> 0 | DM9: =CS9 -> 0 | ... DS9: =CY9 -> 0
A10: 0801 | B10: 16 | C10: 0 | D10: 15 | E10: 0 | F10: 930 | G10: 1074 | H10: 54 | I10: 0 | J10: 0 | M10: 0801 | N10: 7 | O10: 2 | P10: 1 | Q10: 19 | R10: 0 | S10: 6 | T10: 0 | U10: 0 | V10: 0 | W10: 0 | X10: 0 | Y10: 0 | Z10: 0 | AA10: 0 | AB10: 0 | AC10: 0 | AD10: 0 | AE10: 0 | AF10: 0 | AG10: 0 | AH10: 0 | AI10: 0 | AK10: =N10+AK9 -> 74 | AL10: =O10+AL9 -> 57 | AM10: =P10+AM9 -> 34 | AN10: =Q10+AN9 -> 62 | AO10: =R10+AO9 -> 12 | AP10: =S10+AP9 -> 35 | AQ10: =T10+AQ9 -> 6.5 | AR10: =U10+AR9 -> 0 | ... BF10: =AI10+BF9 -> 0 | BI10: =AK10/BJ$5 -> 0.0035238095 | BJ10: =IF(AL10/$BK$5>1,1,AL10/$BK$5) -> 0.0027142857 | BK10: =IF(AM10/$BK$5>1,1,AM10/$BK$5) -> 0.0016190476 | BL10: =IF(AN10/$BK$5>1,1,AN10/$BK$5) -> 0.002952381 | BM10: =IF(AO10/$BK$5>1,1,AO10/$BK$5) -> 0.00057142857 | BN10: =IF(AP10/$BK$5>1,1,AP10/$BK$5) -> 0.0016666667 | BO10: =IF(AQ10/$BK$5>1,1,AQ10/$BK$5) -> 0.00030952381 | BP10: =IF(AR10/$BK$5>1,1,AR10/$BK$5) -> 0 | BQ10: =IF(AS10/$BK$5>1,1,AS10/$BK$5) -> 4.7619048e-05 | ... CD10: =IF(BF10/$BK$5>1,1,BF10/$BK$5) -> 0 | CK10: 0801 | CL10: 0 | CM10: 0 | CN10: 0 | CO10: 0 | CP10: 0 | CQ10: 0 | CR10: 0 | CS10: 0 | CT10: 0 | CU10: 0 | CV10: 0 | CW10: 0 | CX10: 0 | CY10: 0 | CZ10: 0 | DA10: 0 | DB10: 0 | DC10: 0 | DE10: 41852 | DF10: =DF9+CL10 -> 0 | DG10: =DG9+CM10 -> 0 | DH10: =DH9+CN10 -> 2 | DI10: =DI9+CO10 -> 0 | DJ10: =DJ9+CP10 -> 0 | DK10: =DK9+CQ10 -> 6 | DL10: =DL9+CR10 -> 0 | DM10: =DM9+CS10 -> 0 | ... DS10: =DS9+CY10 -> 0
A11: 0802 | B11: 35 | C11: 2 | D11: 6 | E11: 0 | F11: 915 | G11: 1155 | H11: 77 | I11: 0 | J11: 0 | M11: 0802 | N11: 3 | O11: 2 | P11: 4 | Q11: 21 | R11: 2 | S11: 3 | T11: 7 | U11: 0 | V11: 0 | W11: 0 | X11: 0 | Y11: 0 | Z11: 0 | AA11: 0 | AB11: 0 | AC11: 0 | AD11: 0 | AE11: 0 | AF11: 0 | AG11: 0 | AH11: 0 | AI11: 0 | AK11: =N11+AK10 -> 77 | AL11: =O11+AL10 -> 59 | AM11: =P11+AM10 -> 38 | AN11: =Q11+AN10 -> 83 | AO11: =R11+AO10 -> 14 | AP11: =S11+AP10 -> 38 | AQ11: =T11+AQ10 -> 13.5 | AR11: =U11+AR10 -> 0 | ... BF11: =AI11+BF10 -> 0 | BI11: =AK11/BJ$5 -> 0.0036666667 | BJ11: =IF(AL11/$BK$5>1,1,AL11/$BK$5) -> 0.0028095238 | BK11: =IF(AM11/$BK$5>1,1,AM11/$BK$5) -> 0.0018095238 | BL11: =IF(AN11/$BK$5>1,1,AN11/$BK$5) -> 0.003952381 | BM11: =IF(AO11/$BK$5>1,1,AO11/$BK$5) -> 0.00066666667 | BN11: =IF(AP11/$BK$5>1,1,AP11/$BK$5) -> 0.0018095238 | BO11: =IF(AQ11/$BK$5>1,1,AQ11/$BK$5) -> 0.00064285714 | BP11: =IF(AR11/$BK$5>1,1,AR11/$BK$5) -> 0 | BQ11: =IF(AS11/$BK$5>1,1,AS11/$BK$5) -> 4.7619048e-05 | ... CD11: =IF(BF11/$BK$5>1,1,BF11/$BK$5) -> 0 | CK11: 0802 | CL11: 0 | CM11: 0 | CN11: 0 | CO11: 0 | CP11: 0 | CQ11: 0 | CR11: 0 | CS11: 0 | CT11: 0 | CU11: 0 | CV11: 0 | CW11: 0 | CX11: 0 | CY11: 0 | CZ11: 0 | DA11: 0 | DB11: 0 | DC11: 0 | DE11: 41853 | DF11: =DF10+CL11 -> 0 | DG11: =DG10+CM11 -> 0 | DH11: =DH10+CN11 -> 2 | DI11: =DI10+CO11 -> 0 | DJ11: =DJ10+CP11 -> 0 | DK11: =DK10+CQ11 -> 6 | DL11: =DL10+CR11 -> 0 | DM11: =DM10+CS11 -> 0 | ... DS11: =DS10+CY11 -> 0
A12: 0803 | B12: 13 | C12: 1 | D12: 0 | E12: 0 | F12: 412 | G12: 528 | H12: 25 | I12: 0 | J12: 0 | M12: 0803 | N12: 0 | O12: 4 | P12: 6 | Q12: 10 | R12: 3 | S12: 1 | T12: 3 | U12: 0 | V12: 0 | W12: 0 | X12: 0 | Y12: 0 | Z12: 0 | AA12: 0 | AB12: 0 | AC12: 0 | AD12: 0 | AE12: 0 | AF12: 0 | AG12: 0 | AH12: 0 | AI12: 0 | AK12: =N12+AK11 -> 77 | AL12: =O12+AL11 -> 63 | AM12: =P12+AM11 -> 44 | AN12: =Q12+AN11 -> 93 | AO12: =R12+AO11 -> 17 | AP12: =S12+AP11 -> 39 | AQ12: =T12+AQ11 -> 16.5 | AR12: =U12+AR11 -> 0 | ... BF12: =AI12+BF11 -> 0 | BI12: =AK12/BJ$5 -> 0.0036666667 | BJ12: =IF(AL12/$BK$5>1,1,AL12/$BK$5) -> 0.003 | BK12: =IF(AM12/$BK$5>1,1,AM12/$BK$5) -> 0.0020952381 | BL12: =IF(AN12/$BK$5>1,1,AN12/$BK$5) -> 0.0044285714 | BM12: =IF(AO12/$BK$5>1,1,AO12/$BK$5) -> 0.00080952381 | BN12: =IF(AP12/$BK$5>1,1,AP12/$BK$5) -> 0.0018571429 | BO12: =IF(AQ12/$BK$5>1,1,AQ12/$BK$5) -> 0.00078571429 | BP12: =IF(AR12/$BK$5>1,1,AR12/$BK$5) -> 0 | BQ12: =IF(AS12/$BK$5>1,1,AS12/$BK$5) -> 4.7619048e-05 | ... CD12: =IF(BF12/$BK$5>1,1,BF12/$BK$5) -> 0 | CK12: 0803 | CL12: 0 | CM12: 0 | CN12: 0 | CO12: 0 | CP12: 0 | CQ12: 0 | CR12: 0 | CS12: 0 | CT12: 0 | CU12: 0 | CV12: 0 | CW12: 0 | CX12: 0 | CY12: 0 | CZ12: 0 | DA12: 0 | DB12: 0 | DC12: 0 | DE12: 41854 | DF12: =DF11+CL12 -> 0 | DG12: =DG11+CM12 -> 0 | DH12: =DH11+CN12 -> 2 | DI12: =DI11+CO12 -> 0 | DJ12: =DJ11+CP12 -> 0 | DK12: =DK11+CQ12 -> 6 | DL12: =DL11+CR12 -> 0 | DM12: =DM11+CS12 -> 0 | ... DS12: =DS11+CY12 -> 0
A13: 0804 | B13: 14 | C13: 0 | D13: 2 | E13: 1 | F13: 600 | G13: 600 | H13: 55 | I13: 0 | J13: 0 | M13: 0804 | N13: 4 | O13: 0 | P13: 3 | Q13: 20 | R13: 8 | S13: 2 | T13: 12 | U13: 0 | V13: 0 | W13: 0 | X13: 0 | Y13: 0 | Z13: 0 | AA13: 0 | AB13: 0 | AC13: 0 | AD13: 0 | AE13: 0 | AF13: 0 | AG13: 0 | AH13: 0 | AI13: 0 | AK13: =N13+AK12 -> 81 | AL13: =O13+AL12 -> 63 | AM13: =P13+AM12 -> 47 | AN13: =Q13+AN12 -> 113 | AO13: =R13+AO12 -> 25 | AP13: =S13+AP12 -> 41 | AQ13: =T13+AQ12 -> 28.5 | AR13: =U13+AR12 -> 0 | ... BF13: =AI13+BF12 -> 0 | BI13: =AK13/BJ$5 -> 0.0038571429 | BJ13: =IF(AL13/$BK$5>1,1,AL13/$BK$5) -> 0.003 | BK13: =IF(AM13/$BK$5>1,1,AM13/$BK$5) -> 0.0022380952 | BL13: =IF(AN13/$BK$5>1,1,AN13/$BK$5) -> 0.0053809524 | BM13: =IF(AO13/$BK$5>1,1,AO13/$BK$5) -> 0.0011904762 | BN13: =IF(AP13/$BK$5>1,1,AP13/$BK$5) -> 0.001952381 | BO13: =IF(AQ13/$BK$5>1,1,AQ13/$BK$5) -> 0.0013571429 | BP13: =IF(AR13/$BK$5>1,1,AR13/$BK$5) -> 0 | BQ13: =IF(AS13/$BK$5>1,1,AS13/$BK$5) -> 4.7619048e-05 | ... CD13: =IF(BF13/$BK$5>1,1,BF13/$BK$5) -> 0 | CK13: 0804 | CL13: 0 | CM13: 0 | CN13: 0 | CO13: 0 | CP13: 0 | CQ13: 0 | CR13: 0 | CS13: 0 | CT13: 0 | CU13: 0 | CV13: 0 | CW13: 0 | CX13: 0 | CY13: 0 | CZ13: 0 | DA13: 0 | DB13: 0 | DC13: 0 | DE13: 41855 | DF13: =DF12+CL13 -> 0 | DG13: =DG12+CM13 -> 0 | DH13: =DH12+CN13 -> 2 | DI13: =DI12+CO13 -> 0 | DJ13: =DJ12+CP13 -> 0 | DK13: =DK12+CQ13 -> 6 | DL13: =DL12+CR13 -> 0 | DM13: =DM12+CS13 -> 0 | ... DS13: =DS12+CY13 -> 0
A14: 0805 | B14: 30 | C14: 0 | D14: 7 | E14: 1 | F14: 665 | G14: 531 | H14: 35 | I14: 0 | J14: 0 | M14: 0805 | N14: 4 | O14: 1 | P14: 11 | Q14: 16 | R14: 10 | S14: 0 | T14: 4 | U14: 3 | V14: 0 | W14: 0 | X14: 0 | Y14: 0 | Z14: 0 | AA14: 0 | AB14: 0 | AC14: 0 | AD14: 0 | AE14: 0 | AF14: 0 | AG14: 0 | AH14: 0 | AI14: 0 | AK14: =N14+AK13 -> 85 | AL14: =O14+AL13 -> 64 | AM14: =P14+AM13 -> 58 | AN14: =Q14+AN13 -> 129 | AO14: =R14+AO13 -> 35 | AP14: =S14+AP13 -> 41 | AQ14: =T14+AQ13 -> 32.5 | AR14: =U14+AR13 -> 3 | ... BF14: =AI14+BF13 -> 0 | BI14: =AK14/BJ$5 -> 0.004047619 | BJ14: =IF(AL14/$BK$5>1,1,AL14/$BK$5) -> 0.003047619 | BK14: =IF(AM14/$BK$5>1,1,AM14/$BK$5) -> 0.0027619048 | BL14: =IF(AN14/$BK$5>1,1,AN14/$BK$5) -> 0.0061428571 | BM14: =IF(AO14/$BK$5>1,1,AO14/$BK$5) -> 0.0016666667 | BN14: =IF(AP14/$BK$5>1,1,AP14/$BK$5) -> 0.001952381 | BO14: =IF(AQ14/$BK$5>1,1,AQ14/$BK$5) -> 0.001547619 | BP14: =IF(AR14/$BK$5>1,1,AR14/$BK$5) -> 0.00014285714 | BQ14: =IF(AS14/$BK$5>1,1,AS14/$BK$5) -> 4.7619048e-05 | ... CD14: =IF(BF14/$BK$5>1,1,BF14/$BK$5) -> 0 | CK14: 0805 | CL14: 0 | CM14: 0 | CN14: 0 | CO14: 0 | CP14: 0 | CQ14: 0 | CR14: 0 | CS14: 0 | CT14: 0 | CU14: 0 | CV14: 0 | CW14: 0 | CX14: 0 | CY14: 0 | CZ14: 0 | DA14: 0 | DB14: 0 | DC14: 0 | DE14: 41856 | DF14: =DF13+CL14 -> 0 | DG14: =DG13+CM14 -> 0 | DH14: =DH13+CN14 -> 2 | DI14: =DI13+CO14 -> 0 | DJ14: =DJ13+CP14 -> 0 | DK14: =DK13+CQ14 -> 6 | DL14: =DL13+CR14 -> 0 | DM14: =DM13+CS14 -> 0 | ... DS14: =DS13+CY14 -> 0
A15: 0806 | B15: 51 | C15: 1 | D15: 36 | E15: 4 | F15: 1224 | G15: 617 | H15: 103 | I15: 0 | J15: 0 | M15: 0806 | N15: 12 | O15: 2 | P15: 12 | Q15: 26 | R15: 1 | S15: 6 | T15: 12 | U15: 0 | V15: 3 | W15: 0 | X15: 0 | Y15: 0 | Z15: 0 | AA15: 0 | AB15: 0 | AC15: 0 | AD15: 0 | AE15: 0 | AF15: 0 | AG15: 0 | AH15: 0 | AI15: 0 | AK15: =N15+AK14 -> 97 | AL15: =O15+AL14 -> 66 | AM15: =P15+AM14 -> 70 | AN15: =Q15+AN14 -> 155 | AO15: =R15+AO14 -> 36 | AP15: =S15+AP14 -> 47 | AQ15: =T15+AQ14 -> 44.5 | AR15: =U15+AR14 -> 3 | ... BF15: =AI15+BF14 -> 0 | BI15: =AK15/BJ$5 -> 0.0046190476 | BJ15: =IF(AL15/$BK$5>1,1,AL15/$BK$5) -> 0.0031428571 | BK15: =IF(AM15/$BK$5>1,1,AM15/$BK$5) -> 0.0033333333 | BL15: =IF(AN15/$BK$5>1,1,AN15/$BK$5) -> 0.0073809524 | BM15: =IF(AO15/$BK$5>1,1,AO15/$BK$5) -> 0.0017142857 | BN15: =IF(AP15/$BK$5>1,1,AP15/$BK$5) -> 0.0022380952 | BO15: =IF(AQ15/$BK$5>1,1,AQ15/$BK$5) -> 0.0021190476 | BP15: =IF(AR15/$BK$5>1,1,AR15/$BK$5) -> 0.00014285714 | BQ15: =IF(AS15/$BK$5>1,1,AS15/$BK$5) -> 0.00019047619 | ... CD15: =IF(BF15/$BK$5>1,1,BF15/$BK$5) -> 0 | CK15: 0806 | CL15: 1 | CM15: 0 | CN15: 0 | CO15: 0 | CP15: 0 | CQ15: 0 | CR15: 0 | CS15: 0 | CT15: 0 | CU15: 0 | CV15: 0 | CW15: 0 | CX15: 0 | CY15: 0 | CZ15: 0 | DA15: 0 | DB15: 0 | DC15: 0 | DE15: 41857 | DF15: =DF14+CL15 -> 1 | DG15: =DG14+CM15 -> 0 | DH15: =DH14+CN15 -> 2 | DI15: =DI14+CO15 -> 0 | DJ15: =DJ14+CP15 -> 0 | DK15: =DK14+CQ15 -> 6 | DL15: =DL14+CR15 -> 0 | DM15: =DM14+CS15 -> 0 | ... DS15: =DS14+CY15 -> 0
A16: 0807 | B16: 46 | C16: 0 | D16: 8 | E16: 1 | F16: 968 | G16: 311 | H16: 56 | I16: 0 | J16: 0 | M16: 0807 | N16: 42 | O16: 27 | P16: 5 | Q16: 27 | R16: 1 | S16: 7 | T16: 13 | U16: 0 | V16: 0 | W16: 0 | X16: 0 | Y16: 0 | Z16: 0 | AA16: 0 | AB16: 0 | AC16: 0 | AD16: 0 | AE16: 0 | AF16: 0 | AG16: 0 | AH16: 0 | AI16: 0 | AK16: =N16+AK15 -> 139 | AL16: =O16+AL15 -> 93 | AM16: =P16+AM15 -> 75 | AN16: =Q16+AN15 -> 182 | AO16: =R16+AO15 -> 37 | AP16: =S16+AP15 -> 54 | AQ16: =T16+AQ15 -> 57.5 | AR16: =U16+AR15 -> 3 | ... BF16: =AI16+BF15 -> 0 | BI16: =AK16/BJ$5 -> 0.0066190476 | BJ16: =IF(AL16/$BK$5>1,1,AL16/$BK$5) -> 0.0044285714 | BK16: =IF(AM16/$BK$5>1,1,AM16/$BK$5) -> 0.0035714286 | BL16: =IF(AN16/$BK$5>1,1,AN16/$BK$5) -> 0.0086666667 | BM16: =IF(AO16/$BK$5>1,1,AO16/$BK$5) -> 0.0017619048 | BN16: =IF(AP16/$BK$5>1,1,AP16/$BK$5) -> 0.0025714286 | BO16: =IF(AQ16/$BK$5>1,1,AQ16/$BK$5) -> 0.0027380952 | BP16: =IF(AR16/$BK$5>1,1,AR16/$BK$5) -> 0.00014285714 | BQ16: =IF(AS16/$BK$5>1,1,AS16/$BK$5) -> 0.00019047619 | ... CD16: =IF(BF16/$BK$5>1,1,BF16/$BK$5) -> 0 | CK16: 0807 | CL16: 0 | CM16: 0 | CN16: 1 | CO16: 0 | CP16: 0 | CQ16: 0 | CR16: 0 | CS16: 0 | CT16: 0 | CU16: 0 | CV16: 0 | CW16: 0 | CX16: 0 | CY16: 0 | CZ16: 0 | DA16: 0 | DB16: 0 | DC16: 0 | DE16: 41858 | DF16: =DF15+CL16 -> 1 | DG16: =DG15+CM16 -> 0 | DH16: =DH15+CN16 -> 3 | DI16: =DI15+CO16 -> 0 | DJ16: =DJ15+CP16 -> 0 | DK16: =DK15+CQ16 -> 6 | DL16: =DL15+CR16 -> 0 | DM16: =DM15+CS16 -> 0 | ... DS16: =DS15+CY16 -> 0
A17: 0808 | B17: 92 | C17: 0 | D17: 14 | E17: 0 | F17: 704 | G17: 277 | H17: 64 | I17: 0 | J17: 0 | M17: 0808 | N17: 64 | O17: 26 | P17: 14 | Q17: 17 | R17: 0 | S17: 7 | T17: 11 | U17: 6 | V17: 3 | W17: 0 | X17: 0 | Y17: 0 | Z17: 0 | AA17: 0 | AB17: 0 | AC17: 0 | AD17: 0 | AE17: 0 | AF17: 0 | AG17: 0 | AH17: 0 | AI17: 0 | AK17: =N17+AK16 -> 203 | AL17: =O17+AL16 -> 119 | AM17: =P17+AM16 -> 89 | AN17: =Q17+AN16 -> 199 | AO17: =R17+AO16 -> 37 | AP17: =S17+AP16 -> 61 | AQ17: =T17+AQ16 -> 68.5 | AR17: =U17+AR16 -> 9 | ... BF17: =AI17+BF16 -> 0 | BI17: =AK17/BJ$5 -> 0.0096666667 | BJ17: =IF(AL17/$BK$5>1,1,AL17/$BK$5) -> 0.0056666667 | BK17: =IF(AM17/$BK$5>1,1,AM17/$BK$5) -> 0.0042380952 | BL17: =IF(AN17/$BK$5>1,1,AN17/$BK$5) -> 0.0094761905 | BM17: =IF(AO17/$BK$5>1,1,AO17/$BK$5) -> 0.0017619048 | BN17: =IF(AP17/$BK$5>1,1,AP17/$BK$5) -> 0.0029047619 | BO17: =IF(AQ17/$BK$5>1,1,AQ17/$BK$5) -> 0.0032619048 | BP17: =IF(AR17/$BK$5>1,1,AR17/$BK$5) -> 0.00042857143 | BQ17: =IF(AS17/$BK$5>1,1,AS17/$BK$5) -> 0.00033333333 | ... CD17: =IF(BF17/$BK$5>1,1,BF17/$BK$5) -> 0 | CK17: 0808 | CL17: 1 | CM17: 0 | CN17: 0 | CO17: 0 | CP17: 1 | CQ17: 0 | CR17: 0 | CS17: 0 | CT17: 0 | CU17: 0 | CV17: 0 | CW17: 0 | CX17: 0 | CY17: 0 | CZ17: 0 | DA17: 0 | DB17: 0 | DC17: 0 | DE17: 41859 | DF17: =DF16+CL17 -> 2 | DG17: =DG16+CM17 -> 0 | DH17: =DH16+CN17 -> 3 | DI17: =DI16+CO17 -> 0 | DJ17: =DJ16+CP17 -> 1 | DK17: =DK16+CQ17 -> 6 | DL17: =DL16+CR17 -> 0 | DM17: =DM16+CS17 -> 0 | ... DS17: =DS16+CY17 -> 0
A18: 0809 | B18: 41 | C18: 0 | D18: 17 | E18: 6 | F18: 555 | G18: 174 | H18: 35 | I18: 0 | J18: 0 | M18: 0809 | N18: 27 | O18: 51 | P18: 11 | Q18: 18 | R18: 0 | S18: 3 | T18: 8 | U18: 3 | V18: 6 | W18: 0 | X18: 0 | Y18: 0 | Z18: 0 | AA18: 0 | AB18: 0 | AC18: 0 | AD18: 0 | AE18: 0 | AF18: 0 | AG18: 0 | AH18: 0 | AI18: 0 | AK18: =N18+AK17 -> 230 | AL18: =O18+AL17 -> 170 | AM18: =P18+AM17 -> 100 | AN18: =Q18+AN17 -> 217 | AO18: =R18+AO17 -> 37 | AP18: =S18+AP17 -> 64 | AQ18: =T18+AQ17 -> 76.5 | AR18: =U18+AR17 -> 12 | ... BF18: =AI18+BF17 -> 0 | BI18: =AK18/BJ$5 -> 0.010952381 | BJ18: =IF(AL18/$BK$5>1,1,AL18/$BK$5) -> 0.0080952381 | BK18: =IF(AM18/$BK$5>1,1,AM18/$BK$5) -> 0.0047619048 | BL18: =IF(AN18/$BK$5>1,1,AN18/$BK$5) -> 0.010333333 | BM18: =IF(AO18/$BK$5>1,1,AO18/$BK$5) -> 0.0017619048 | BN18: =IF(AP18/$BK$5>1,1,AP18/$BK$5) -> 0.003047619 | BO18: =IF(AQ18/$BK$5>1,1,AQ18/$BK$5) -> 0.0036428571 | BP18: =IF(AR18/$BK$5>1,1,AR18/$BK$5) -> 0.00057142857 | BQ18: =IF(AS18/$BK$5>1,1,AS18/$BK$5) -> 0.00061904762 | ... CD18: =IF(BF18/$BK$5>1,1,BF18/$BK$5) -> 0 | CK18: 0809 | CL18: 0 | CM18: 0 | CN18: 0 | CO18: 1 | CP18: 0 | CQ18: 0 | CR18: 0 | CS18: 0 | CT18: 0 | CU18: 0 | CV18: 0 | CW18: 0 | CX18: 0 | CY18: 0 | CZ18: 0 | DA18: 0 | DB18: 0 | DC18: 0 | DE18: 41860 | DF18: =DF17+CL18 -> 2 | DG18: =DG17+CM18 -> 0 | DH18: =DH17+CN18 -> 3 | DI18: =DI17+CO18 -> 1 | DJ18: =DJ17+CP18 -> 1 | DK18: =DK17+CQ18 -> 6 | DL18: =DL17+CR18 -> 0 | DM18: =DM17+CS18 -> 0 | ... DS18: =DS17+CY18 -> 0
A19: 0810 | B19: 84 | C19: 1 | D19: 33 | E19: 0 | F19: 732 | G19: 188 | H19: 27 | I19: 0 | J19: 0 | M19: 0810 | N19: 61 | O19: 23 | P19: 44 | Q19: 52 | R19: 2 | S19: 3 | T19: 8.5 | U19: 3 | V19: 15 | W19: 0 | X19: 0 | Y19: 0 | Z19: 0 | AA19: 0 | AB19: 0 | AC19: 0 | AD19: 0 | AE19: 0 | AF19: 0 | AG19: 0 | AH19: 0 | AI19: 0 | AK19: =N19+AK18 -> 291 | AL19: =O19+AL18 -> 193 | AM19: =P19+AM18 -> 144 | AN19: =Q19+AN18 -> 269 | AO19: =R19+AO18 -> 39 | AP19: =S19+AP18 -> 67 | AQ19: =T19+AQ18 -> 85 | AR19: =U19+AR18 -> 15 | ... BF19: =AI19+BF18 -> 0 | BI19: =AK19/BJ$5 -> 0.013857143 | BJ19: =IF(AL19/$BK$5>1,1,AL19/$BK$5) -> 0.0091904762 | BK19: =IF(AM19/$BK$5>1,1,AM19/$BK$5) -> 0.0068571429 | BL19: =IF(AN19/$BK$5>1,1,AN19/$BK$5) -> 0.012809524 | BM19: =IF(AO19/$BK$5>1,1,AO19/$BK$5) -> 0.0018571429 | BN19: =IF(AP19/$BK$5>1,1,AP19/$BK$5) -> 0.0031904762 | BO19: =IF(AQ19/$BK$5>1,1,AQ19/$BK$5) -> 0.004047619 | BP19: =IF(AR19/$BK$5>1,1,AR19/$BK$5) -> 0.00071428571 | BQ19: =IF(AS19/$BK$5>1,1,AS19/$BK$5) -> 0.0013333333 | ... CD19: =IF(BF19/$BK$5>1,1,BF19/$BK$5) -> 0 | CK19: 0810 | CL19: 0 | CM19: 0 | CN19: 0 | CO19: 1 | CP19: 0 | CQ19: 1 | CR19: 0 | CS19: 0 | CT19: 0 | CU19: 0 | CV19: 0 | CW19: 0 | CX19: 0 | CY19: 0 | CZ19: 0 | DA19: 0 | DB19: 0 | DC19: 0 | DE19: 41861 | DF19: =DF18+CL19 -> 2 | DG19: =DG18+CM19 -> 0 | DH19: =DH18+CN19 -> 3 | DI19: =DI18+CO19 -> 2 | DJ19: =DJ18+CP19 -> 1 | DK19: =DK18+CQ19 -> 7 | DL19: =DL18+CR19 -> 0 | DM19: =DM18+CS19 -> 0 | ... DS19: =DS18+CY19 -> 0
A20: 0811 | B20: 57 | C20: 0 | D20: 86 | E20: 0 | F20: 689 | G20: 159 | H20: 27 | I20: 0 | J20: 0 | M20: 0811 | N20: 26 | O20: 16 | P20: 43 | Q20: 60 | R20: 0 | S20: 2 | T20: 16 | U20: 12 | V20: 8 | W20: 0 | X20: 0 | Y20: 0 | Z20: 0 | AA20: 0 | AB20: 0 | AC20: 0 | AD20: 0 | AE20: 0 | AF20: 0 | AG20: 0 | AH20: 0 | AI20: 0 | AK20: =N20+AK19 -> 317 | AL20: =O20+AL19 -> 209 | AM20: =P20+AM19 -> 187 | AN20: =Q20+AN19 -> 329 | AO20: =R20+AO19 -> 39 | AP20: =S20+AP19 -> 69 | AQ20: =T20+AQ19 -> 101 | AR20: =U20+AR19 -> 27 | ... BF20: =AI20+BF19 -> 0 | BI20: =AK20/BJ$5 -> 0.015095238 | BJ20: =IF(AL20/$BK$5>1,1,AL20/$BK$5) -> 0.009952381 | BK20: =IF(AM20/$BK$5>1,1,AM20/$BK$5) -> 0.0089047619 | BL20: =IF(AN20/$BK$5>1,1,AN20/$BK$5) -> 0.015666667 | BM20: =IF(AO20/$BK$5>1,1,AO20/$BK$5) -> 0.0018571429 | BN20: =IF(AP20/$BK$5>1,1,AP20/$BK$5) -> 0.0032857143 | BO20: =IF(AQ20/$BK$5>1,1,AQ20/$BK$5) -> 0.0048095238 | BP20: =IF(AR20/$BK$5>1,1,AR20/$BK$5) -> 0.0012857143 | BQ20: =IF(AS20/$BK$5>1,1,AS20/$BK$5) -> 0.0017142857 | ... CD20: =IF(BF20/$BK$5>1,1,BF20/$BK$5) -> 0 | CK20: 0811 | CL20: 0 | CM20: 0 | CN20: 0 | CO20: 0 | CP20: 0 | CQ20: 1 | CR20: 0 | CS20: 0 | CT20: 0 | CU20: 0 | CV20: 0 | CW20: 0 | CX20: 0 | CY20: 0 | CZ20: 0 | DA20: 0 | DB20: 0 | DC20: 0 | DE20: 41862 | DF20: =DF19+CL20 -> 2 | DG20: =DG19+CM20 -> 0 | DH20: =DH19+CN20 -> 3 | DI20: =DI19+CO20 -> 2 | DJ20: =DJ19+CP20 -> 1 | DK20: =DK19+CQ20 -> 8 | DL20: =DL19+CR20 -> 0 | DM20: =DM19+CS20 -> 0 | ... DS20: =DS19+CY20 -> 0
A21: 0812 | B21: 135 | C21: 1 | D21: 66 | E21: 4 | F21: 594 | G21: 165 | H21: 16 | I21: 0 | J21: 0 | M21: 0812 | N21: 55 | O21: 9 | P21: 33 | Q21: 98 | R21: 5 | S21: 9 | T21: 36 | U21: 15 | V21: 15 | W21: 0 | X21: 0 | Y21: 0 | Z21: 0 | AA21: 0 | AB21: 0 | AC21: 0 | AD21: 0 | AE21: 0 | AF21: 0 | AG21: 0 | AH21: 0 | AI21: 0 | AK21: =N21+AK20 -> 372 | AL21: =O21+AL20 -> 218 | AM21: =P21+AM20 -> 220 | AN21: =Q21+AN20 -> 427 | AO21: =R21+AO20 -> 44 | AP21: =S21+AP20 -> 78 | AQ21: =T21+AQ20 -> 137 | AR21: =U21+AR20 -> 42 | ... BF21: =AI21+BF20 -> 0 | BI21: =AK21/BJ$5 -> 0.017714286 | BJ21: =IF(AL21/$BK$5>1,1,AL21/$BK$5) -> 0.010380952 | BK21: =IF(AM21/$BK$5>1,1,AM21/$BK$5) -> 0.01047619 | BL21: =IF(AN21/$BK$5>1,1,AN21/$BK$5) -> 0.020333333 | BM21: =IF(AO21/$BK$5>1,1,AO21/$BK$5) -> 0.0020952381 | BN21: =IF(AP21/$BK$5>1,1,AP21/$BK$5) -> 0.0037142857 | BO21: =IF(AQ21/$BK$5>1,1,AQ21/$BK$5) -> 0.0065238095 | BP21: =IF(AR21/$BK$5>1,1,AR21/$BK$5) -> 0.002 | BQ21: =IF(AS21/$BK$5>1,1,AS21/$BK$5) -> 0.0024285714 | ... CD21: =IF(BF21/$BK$5>1,1,BF21/$BK$5) -> 0 | CK21: 0812 | CL21: 0 | CM21: 0 | CN21: 0 | CO21: 0 | CP21: 0 | CQ21: 1 | CR21: 0 | CS21: 0 | CT21: 0 | CU21: 0 | CV21: 0 | CW21: 0 | CX21: 0 | CY21: 0 | CZ21: 0 | DA21: 0 | DB21: 0 | DC21: 0 | DE21: 41863 | DF21: =DF20+CL21 -> 2 | DG21: =DG20+CM21 -> 0 | DH21: =DH20+CN21 -> 3 | DI21: =DI20+CO21 -> 2 | DJ21: =DJ20+CP21 -> 1 | DK21: =DK20+CQ21 -> 9 | DL21: =DL20+CR21 -> 0 | DM21: =DM20+CS21 -> 0 | ... DS21: =DS20+CY21 -> 0
... A131: 1130 | B131: 0 | C131: 0 | D131: 0 | E131: 2 | F131: 0 | G131: 0 | H131: 0 | I131: 0 | J131: 0 | M131: 1130 | N131: 0 | O131: 0 | P131: 0 | Q131: 0 | R131: 0 | S131: 0 | T131: 0 | U131: 0 | V131: 0 | W131: 0 | X131: 0 | Y131: 0 | Z131: 0 | AA131: 0 | AB131: 0 | AC131: 0 | AD131: 0 | AE131: 0 | AF131: 0 | AG131: 0 | AH131: 0 | AI131: 0 | AK131: =N131+AK130 -> 61962 | AL131: =O131+AL130 -> 54679 | AM131: =P131+AM130 -> 38594.5 | AN131: =Q131+AN130 -> 34605.69 | AO131: =R131+AO130 -> 44384.5 | AP131: =S131+AP130 -> 41473.5 | AQ131: =T131+AQ130 -> 47232.5 | AR131: =U131+AR130 -> 54789.99 | ... BF131: =AI131+BF130 -> 27706 | BI131: =AK131/BJ$5 -> 2.9505714 | BJ131: =IF(AL131/$BK$5>1,1,AL131/$BK$5) -> 1 | BK131: =IF(AM131/$BK$5>1,1,AM131/$BK$5) -> 1 | BL131: =IF(AN131/$BK$5>1,1,AN131/$BK$5) -> 1 | BM131: =IF(AO131/$BK$5>1,1,AO131/$BK$5) -> 1 | BN131: =IF(AP131/$BK$5>1,1,AP131/$BK$5) -> 1 | BO131: =IF(AQ131/$BK$5>1,1,AQ131/$BK$5) -> 1 | BP131: =IF(AR131/$BK$5>1,1,AR131/$BK$5) -> 1 | BQ131: =IF(AS131/$BK$5>1,1,AS131/$BK$5) -> 0.74977706 | ... CD131: =IF(BF131/$BK$5>1,1,BF131/$BK$5) -> 1 | CK131: 1130 | CL131: 0 | CM131: 0 | CN131: 0 | CO131: 0 | CP131: 0 | CQ131: 0 | CR131: 0 | CS131: 0 | CT131: 0 | CU131: 0 | CV131: 0 | CW131: 0 | CX131: 0 | CY131: 0 | CZ131: 0 | DA131: 0 | DB131: 0 | DC131: 0 | DE131: 41973 | DF131: =DF130+CL131 -> 2961.66 | DG131: =DG130+CM131 -> 1567.5 | DH131: =DH130+CN131 -> 9459.5 | DI131: =DI130+CO131 -> 5203.5 | DJ131: =DJ130+CP131 -> 1805.5 | DK131: =DK130+CQ131 -> 6076.6818 | DL131: =DL130+CR131 -> 661.5 | DM131: =DM130+CS131 -> 2133 | ... DS131: =DS130+CY131 -> 911
A132: Grand Total | B132: 168682.16 | C132: 9385 | D132: 45002.93 | E132: 6306 | F132: 312787.1 | G132: 133073 | H132: 2288.5 | I132: 124 | J132: 38 | M132: Grand Total | N132: 61962 | O132: 54679 | P132: 38594.5 | Q132: 34605.69 | R132: 44384.5 | S132: 41473.5 | T132: 47232.5 | U132: 54789.99 | V132: 15745.318 | W132: 28571.855 | X132: 14944 | Y132: 26269 | Z132: 24942 | AA132: 11646 | AB132: 21080 | AC132: 16953 | AD132: 52773 | AE132: 28935 | AF132: 64808 | AG132: 40227.75 | AH132: 32690 | AI132: 27706 | CK132: Grand Total | CL132: 2961.66 | CM132: 1567.5 | CN132: 9459.5 | CO132: 5203.5 | CP132: 1805.5 | CQ132: 6076.6818 | CR132: 661.5 | CS132: 2133 | CT132: 708 | CU132: 1369 | CV132: 3839 | CW132: 925 | CX132: 2034 | CY132: 911 | CZ132: 5813 | DA132: 2487 | DB132: 5496 | DC132: 2438
B136: Data
A137: YEAR | B137: Sum of CN | C137: Sum of JCN
A138: 1986 | B138: 35121 | C138: 0
A139: 1987 | B139: 53216 | C139: 0
A140: 1988 | B140: 66171 | C140: 10149
A141: 1989 | B141: 60316 | C141: 16023
A142: 1990 | B142: 117106 | C142: 18149
A143: 1991 | B143: 114414 | C143: 17843
A144: 1992 | B144: 140805 | C144: 4056
A145: 1993 | B145: 96257 | C145: 1808
A146: 1994 | B146: 57678 | C146: 957
A147: 1995 | B147: 27162 | C147: 2500
A148: 1996 | B148: 27338 | C148: 1796
A149: 1997 | B149: 26115 | C149: 643
... A174: 2022 | B174: 72900.6 | C174: 5625
A175: 2023 | B175: 95781.56 | C175: 3760 | E175: YEAR | F175: Sum of ST | G175: Sum of ST | H175: TOTAL
A176: Grand Total | B176: 1770352.8 | C176: 157809.84 | E176: 2017 | F176: 1544 | G176: 108.47 | H176: =SUM(F176:G176) -> 1652.47
E177: 2016 | F177: 636.1 | G177: 29.41 | H177: =SUM(F177:G177) -> 665.51
...

Sheet FINAL_ESC (with adj)
A1: FINAL Escapement Estimates. | M1: Coho clip rate from unexpanded and uninterpolated counts is found on CO mark rate tab
A2: Final Chinook estimates from yearly Stamp CN Summary.xls files (including adjustments by Jeff Till between jack/adult numbers) | M2: The table below is the total estimated number of clipped/unclipped/not checked adult and jack coho
A3: Final coho estimates from 'Summary' tab. Any adjustments to coho estimates are described below. | M3: Includes expansions and interpolations
M5: Year | N5: Coho Adults | Q5: Coho Jacks | T5: Adjustment | U5: file
A6: Year | B6: Adult chinook | C6: Jack Chinook | D6: Adult Coho | E6: Jack Coho | F6: Adjustments | G6: Date revised | H6: File | N6: not checked | O6: unclipped | P6: clipped | Q6: not checked | R6: unclipped | S6: clipped
A7: 2015 | B7: 55476.28 | C7: 1781.72 | D7: 12776 | E7: 2748 | F7: Assumed 662 CN jacks had been counted as coho. Reduced adult coho count by 662, increased CN jack count by 662. Jeff Till | G7: 42401 | H7: Rbt2015\Stamp CN Summary, 2015.xlsx | M7: 2015 | N7: 329 | O7: 5141 | P7: 7306 | Q7: 183 | R7: 1867.24 | S7: 697.5 | T7: clip rates were applied to new adult coho total (13438-662 adults) | U7: X:\WCVI\SOCKEYE\SOMASS\Data\ESCAPEMENT_PROGRAM\Somass 2015\2015 Inseason Somass Counts.xlsx
A8: 2016 | B8: 46859 | C8: 6294 | D8: 23001.5 | E8: 3718 | F8: 716 adult coho removed and added as Chinook jacks. (Revised jack catch sample rate to be the same as rate for adult males, and reduced the SF estimate of coho by an equivalent 716 fish. ) Jeff Till. | G8: 42767 | H8: Rbt2016\Stamp CN Summary, 2016.xlsx | M8: 2016 | N8: 1669.0453 | O8: 10821.155 | P8: 10511.3 | Q8: 494 | R8: 2304 | S8: 920 | T8: clip rates were applied to new adult coho total (23718 adults-716adults) | U8: ..\..\SOCKEYE\SOMASS\Data\ESCAPEMENT_PROGRAM\Somass 2016\2016 Final Post-Season Somass Counts.xlsx

Sheet CN Graph
B2: NB 1996-2011 are all daytime counts only except for 1998 which includes nighttime counts due to 24 hour fishway operation that year.
B3: 2012 to 2018 include both day and night counts. Would reduce by approx 30% to equate to previous years.
F32: Expected Escapement | Z32: Use this to set the scale of the chart. | AE32: Jeffs updated prediction | AF32: Predicted PSARC total esc. | AG32: Predicted nighttime migration | AH32: predicted daytime migration | BI32: Cumulative chinook Jacks | BK32: Estimated Escapement
F33: 21000 | G33: Escapement target in 2022 = 21000 | BK33: 2823 | BL33: in 2019: used avg jack esc from 2006-2018
F34: 21000 | AF34: 35000 | AG34: =0*AF34 -> 0 | AH34: =AF34-AG34 -> 35000 | BI34: Daytime migration forecast ( used to use 85% of total). | BK34: 2823
H35: =MAX($C$41:$C$163)*1/(VLOOKUP(CONCATENATE(DAY(TODAY()),"-",TEXT(TODAY(),"mmm")),$Z$40:$AY$163,19,FALSE)) -> #N/A | I35: = projected based on average proportion of escapement to date
H36: =MAX($C$41:$C$163)*1/(VLOOKUP(CONCATENATE(DAY(TODAY()),"-",TEXT(TODAY(),"mmm")),$Z$40:$AY$163,20,FALSE)) -> #N/A | I36: = projected based on lower 90% quantile of escapement to date
H37: =MAX($C$41:$C$163)*1/(VLOOKUP(CONCATENATE(DAY(TODAY()),"-",TEXT(TODAY(),"mmm")),$Z$40:$AY$163,21,FALSE)) -> #N/A | I37: = projected based on upper 90% quantile of escapement to date
B39: CUMULATIVE DAILY ADULT CHINOOK ESCAPEMENT THROUGH STAMP FALLS | Z39: CUMULATIVE % OF 21000 ADULT CHINOOK ESCAPEMENT THROUGH STAMP FALLS | BI39: CUMULATIVE DAILY JACK CHINOOK ESCAPEMENT THROUGH STAMP FALLS | BY39: CUMULATIVE % OF FINAL JACK CHINOOK ESCAPEMENT THROUGH STAMP FALLS (current year based on expected escapement)
B40: DATE | C40: 2022 | D40: 2021 | E40: 2020 | F40: 2019 | G40: 2018 | H40: 2017 | I40: 2016 | J40: 2015 | K40: 2014 | L40: 2013 | M40: 2012 | N40: 2011 | O40: 2010 | P40: 2009 | Q40: 2008 | R40: 2007 | S40: 2006 | T40: 2005 | U40: 2004 | V40: 2003 | W40: 2002 | X40: 2001 | Z40: DATE | AA40: 2022 | AB40: 2021 | AC40: 2020 | AD40: 2019 | AE40: 2018 | AF40: 2017 | AG40: 2016 | AH40: 2015 | AI40: 2014 | AJ40: 2013 | AK40: 2012 | AL40: 2011 | AM40: 2010 | AN40: 2009 | AO40: 2008 | AP40: 2007 | AQ40: 2006 | AR40: 2005 | AS40: 2004 | AT40: 2003 | AU40: 2002 | AV40: 2001 | AW40: average | AX40: l90 | AY40: u90 | BI40: STDATE | BJ40: 2019 | BK40: 2018 | BL40: 2017 | BM40: 2016 | BN40: 2015 | BO40: 2014 | BP40: 2013 | BQ40: 2012 | BR40: 2011 | BS40: 2010 | BT40: 2009 | BU40: 2008 | BV40: 2007 | BW40: 2006 | BY40: STDATE | BZ40: 2019 | CA40: 2018 | CB40: 2017 | CC40: 2016 | CD40: 2015 | CE40: 2014 | CF40: 2013 | CG40: 2012 | CH40: 2011 | CI40: 2010 | CJ40: 2009 | CK40: 2008 | CL40: 2007 | CM40: 2006 | CN40: average | CO40: (with 1 st.dev.)
B41: =' STAMP Summary'!A9 -> 0731 | C41: =' STAMP Summary'!AK9 -> 67 | D41: =' STAMP Summary'!AL9 -> 55 | E41: =' STAMP Summary'!AM9 -> 33 | F41: =' STAMP Summary'!AN9 -> 43 | G41: =' STAMP Summary'!AO9 -> 12 | H41: =' STAMP Summary'!AP9 -> 29 | I41: =' STAMP Summary'!AQ9 -> 6.5 | J41: =' STAMP Summary'!AR9 -> 0 | ... X41: =' STAMP Summary'!BF9 -> 0 | Z41: =CONCATENATE(DAY(B41),"-",TEXT(B41,"MMM")) -> 31-Dec | AA41: =' STAMP Summary'!BI9 -> 0.0031904762 | AB41: =' STAMP Summary'!BJ9 -> 0.0026190476 | AC41: =' STAMP Summary'!BK9 -> 0.0015714286 | AD41: =' STAMP Summary'!BL9 -> 0.002047619 | AE41: =' STAMP Summary'!BM9 -> 0.00057142857 | AF41: =' STAMP Summary'!BN9 -> 0.0013809524 | AG41: =' STAMP Summary'!BO9 -> 0.00030952381 | AH41: =' STAMP Summary'!BP9 -> 0 | ... AV41: =' STAMP Summary'!CD9 -> 0 | AW41: =AVERAGE(AB41:AH41,AJ41,AL41:AM41,AO41,AQ41:AV41) -> 0.0005 | AX41: =_xlfn.PERCENTILE.INC((AB41:AH41,AJ41,AL41:AM41,AO41,AQ41:AV41),0.05) -> 0 | AY41: =_xlfn.PERCENTILE.INC((AB41:AH41,AJ41,AL41:AM41,AO41,AQ41:AV41),0.95) -> 0.0021619048 | BI41: =' STAMP Summary'!DE9 -> 41851 | BJ41: =' STAMP Summary'!DF9 -> 0 | BK41: =' STAMP Summary'!DG9 -> 0 | BL41: =' STAMP Summary'!DH9 -> 2 | BM41: =' STAMP Summary'!DI9 -> 0 | BN41: =' STAMP Summary'!DJ9 -> 0 | BO41: =' STAMP Summary'!DK9 -> 6 | BP41: =' STAMP Summary'!DL9 -> 0 | ... BW41: =' STAMP Summary'!DS9 -> 0 | BY41: =BI41 -> 41851 | BZ41: =$BK$34*CN41 -> 0.67684736 | CA41: =BK41/$BK$163 -> 0 | CB41: =BL41/BL$163 -> 0.00021142767 | CC41: =BM41/BM$163 -> 0 | CD41: =BN41/BN$163 -> 0 | CE41: =BO41/BO$163 -> 0.00098738097 | CF41: =BP41/BP$163 -> 0 | CG41: =BQ41/BQ$163 -> 0 | CH41: =BR41/BR$163 -> 0 | CI41: =BS41/BS$163 -> 0 | ... CM41: =BW41/BW$163 -> 0 | CN41: =AVERAGE(CA41:CE41) -> 0.00023976173 | CO41: =STDEV(CA41:CE41) -> 0.0004278418
B42: =' STAMP Summary'!A10 -> 0801 | C42: =' STAMP Summary'!AK10 -> 74 | D42: =' STAMP Summary'!AL10 -> 57 | E42: =' STAMP Summary'!AM10 -> 34 | F42: =' STAMP Summary'!AN10 -> 62 | G42: =' STAMP Summary'!AO10 -> 12 | H42: =' STAMP Summary'!AP10 -> 35 | I42: =' STAMP Summary'!AQ10 -> 6.5 | J42: =' STAMP Summary'!AR10 -> 0 | ... X42: =' STAMP Summary'!BF10 -> 0 | Z42: =CONCATENATE(DAY(B42),"-",TEXT(B42,"MMM")) -> 11-Mar | AA42: =' STAMP Summary'!BI10 -> 0.0035238095 | AB42: =' STAMP Summary'!BJ10 -> 0.0027142857 | AC42: =' STAMP Summary'!BK10 -> 0.0016190476 | AD42: =' STAMP Summary'!BL10 -> 0.002952381 | AE42: =' STAMP Summary'!BM10 -> 0.00057142857 | AF42: =' STAMP Summary'!BN10 -> 0.0016666667 | AG42: =' STAMP Summary'!BO10 -> 0.00030952381 | AH42: =' STAMP Summary'!BP10 -> 0 | ... AV42: =' STAMP Summary'!CD10 -> 0 | AW42: =AVERAGE(AB42:AH42,AJ42,AL42:AM42,AO42,AQ42:AV42) -> 0.00057843137 | AX42: =_xlfn.PERCENTILE.INC((AB42:AH42,AJ42,AL42:AM42,AO42,AQ42:AV42),0.05) -> 0 | AY42: =_xlfn.PERCENTILE.INC((AB42:AH42,AJ42,AL42:AM42,AO42,AQ42:AV42),0.95) -> 0.0027619048 | BI42: =' STAMP Summary'!DE10 -> 41852 | BJ42: =' STAMP Summary'!DF10 -> 0 | BK42: =' STAMP Summary'!DG10 -> 0 | BL42: =' STAMP Summary'!DH10 -> 2 | BM42: =' STAMP Summary'!DI10 -> 0 | BN42: =' STAMP Summary'!DJ10 -> 0 | BO42: =' STAMP Summary'!DK10 -> 6 | BP42: =' STAMP Summary'!DL10 -> 0 | ... BW42: =' STAMP Summary'!DS10 -> 0 | BY42: =BI42 -> 41852 | BZ42: =$BK$34*CN42 -> 0.67684736 | CA42: =BK42/$BK$163 -> 0 | CB42: =BL42/BL$163 -> 0.00021142767 | CC42: =BM42/BM$163 -> 0 | CD42: =BN42/BN$163 -> 0 | CE42: =BO42/BO$163 -> 0.00098738097 | CF42: =BP42/BP$163 -> 0 | CG42: =BQ42/BQ$163 -> 0 | CH42: =BR42/BR$163 -> 0 | CI42: =BS42/BS$163 -> 0 | ... CM42: =BW42/BW$163 -> 0 | CN42: =AVERAGE(CA42:CE42) -> 0.00023976173 | CO42: =STDEV(CA42:CE42) -> 0.0004278418
B43: =' STAMP Summary'!A11 -> 0802 | C43: =' STAMP Summary'!AK11 -> 77 | D43: =' STAMP Summary'!AL11 -> 59 | E43: =' STAMP Summary'!AM11 -> 38 | F43: =' STAMP Summary'!AN11 -> 83 | G43: =' STAMP Summary'!AO11 -> 14 | H43: =' STAMP Summary'!AP11 -> 38 | I43: =' STAMP Summary'!AQ11 -> 13.5 | J43: =' STAMP Summary'!AR11 -> 0 | ... X43: =' STAMP Summary'!BF11 -> 0 | Z43: =CONCATENATE(DAY(B43),"-",TEXT(B43,"MMM")) -> 12-Mar | AA43: =' STAMP Summary'!BI11 -> 0.0036666667 | AB43: =' STAMP Summary'!BJ11 -> 0.0028095238 | AC43: =' STAMP Summary'!BK11 -> 0.0018095238 | AD43: =' STAMP Summary'!BL11 -> 0.003952381 | AE43: =' STAMP Summary'!BM11 -> 0.00066666667 | AF43: =' STAMP Summary'!BN11 -> 0.0018095238 | AG43: =' STAMP Summary'!BO11 -> 0.00064285714 | AH43: =' STAMP Summary'!BP11 -> 0 | ... AV43: =' STAMP Summary'!CD11 -> 0 | AW43: =AVERAGE(AB43:AH43,AJ43,AL43:AM43,AO43,AQ43:AV43) -> 0.00068767507 | AX43: =_xlfn.PERCENTILE.INC((AB43:AH43,AJ43,AL43:AM43,AO43,AQ43:AV43),0.05) -> 0 | AY43: =_xlfn.PERCENTILE.INC((AB43:AH43,AJ43,AL43:AM43,AO43,AQ43:AV43),0.95) -> 0.0030380952 | BI43: =' STAMP Summary'!DE11 -> 41853 | BJ43: =' STAMP Summary'!DF11 -> 0 | BK43: =' STAMP Summary'!DG11 -> 0 | BL43: =' STAMP Summary'!DH11 -> 2 | BM43: =' STAMP Summary'!DI11 -> 0 | BN43: =' STAMP Summary'!DJ11 -> 0 | BO43: =' STAMP Summary'!DK11 -> 6 | BP43: =' STAMP Summary'!DL11 -> 0 | ... BW43: =' STAMP Summary'!DS11 -> 0 | BY43: =BI43 -> 41853 | BZ43: =$BK$34*CN43 -> 0.67684736 | CA43: =BK43/$BK$163 -> 0 | CB43: =BL43/BL$163 -> 0.00021142767 | CC43: =BM43/BM$163 -> 0 | CD43: =BN43/BN$163 -> 0 | CE43: =BO43/BO$163 -> 0.00098738097 | CF43: =BP43/BP$163 -> 0 | CG43: =BQ43/BQ$163 -> 0 | CH43: =BR43/BR$163 -> 0 | CI43: =BS43/BS$163 -> 0 | ... CM43: =BW43/BW$163 -> 0 | CN43: =AVERAGE(CA43:CE43) -> 0.00023976173 | CO43: =STDEV(CA43:CE43) -> 0.0004278418
B44: =' STAMP Summary'!A12 -> 0803 | C44: =' STAMP Summary'!AK12 -> 77 | D44: =' STAMP Summary'!AL12 -> 63 | E44: =' STAMP Summary'!AM12 -> 44 | F44: =' STAMP Summary'!AN12 -> 93 | G44: =' STAMP Summary'!AO12 -> 17 | H44: =' STAMP Summary'!AP12 -> 39 | I44: =' STAMP Summary'!AQ12 -> 16.5 | J44: =' STAMP Summary'!AR12 -> 0 | ... X44: =' STAMP Summary'!BF12 -> 0 | Z44: =CONCATENATE(DAY(B44),"-",TEXT(B44,"MMM")) -> 13-Mar | AA44: =' STAMP Summary'!BI12 -> 0.0036666667 | AB44: =' STAMP Summary'!BJ12 -> 0.003 | AC44: =' STAMP Summary'!BK12 -> 0.0020952381 | AD44: =' STAMP Summary'!BL12 -> 0.0044285714 | AE44: =' STAMP Summary'!BM12 -> 0.00080952381 | AF44: =' STAMP Summary'!BN12 -> 0.0018571429 | AG44: =' STAMP Summary'!BO12 -> 0.00078571429 | AH44: =' STAMP Summary'!BP12 -> 0 | ... AV44: =' STAMP Summary'!CD12 -> 0 | AW44: =AVERAGE(AB44:AH44,AJ44,AL44:AM44,AO44,AQ44:AV44) -> 0.00076330532 | AX44: =_xlfn.PERCENTILE.INC((AB44:AH44,AJ44,AL44:AM44,AO44,AQ44:AV44),0.05) -> 0 | AY44: =_xlfn.PERCENTILE.INC((AB44:AH44,AJ44,AL44:AM44,AO44,AQ44:AV44),0.95) -> 0.0032857143 | BI44: =' STAMP Summary'!DE12 -> 41854 | BJ44: =' STAMP Summary'!DF12 -> 0 | BK44: =' STAMP Summary'!DG12 -> 0 | BL44: =' STAMP Summary'!DH12 -> 2 | BM44: =' STAMP Summary'!DI12 -> 0 | BN44: =' STAMP Summary'!DJ12 -> 0 | BO44: =' STAMP Summary'!DK12 -> 6 | BP44: =' STAMP Summary'!DL12 -> 0 | ... BW44: =' STAMP Summary'!DS12 -> 0 | BY44: =BI44 -> 41854 | BZ44: =$BK$34*CN44 -> 0.67684736 | CA44: =BK44/$BK$163 -> 0 | CB44: =BL44/BL$163 -> 0.00021142767 | CC44: =BM44/BM$163 -> 0 | CD44: =BN44/BN$163 -> 0 | CE44: =BO44/BO$163 -> 0.00098738097 | CF44: =BP44/BP$163 -> 0 | CG44: =BQ44/BQ$163 -> 0 | CH44: =BR44/BR$163 -> 0 | CI44: =BS44/BS$163 -> 0 | ... CM44: =BW44/BW$163 -> 0 | CN44: =AVERAGE(CA44:CE44) -> 0.00023976173 | CO44: =STDEV(CA44:CE44) -> 0.0004278418
B45: =' STAMP Summary'!A13 -> 0804 | C45: =' STAMP Summary'!AK13 -> 81 | D45: =' STAMP Summary'!AL13 -> 63 | E45: =' STAMP Summary'!AM13 -> 47 | F45: =' STAMP Summary'!AN13 -> 113 | G45: =' STAMP Summary'!AO13 -> 25 | H45: =' STAMP Summary'!AP13 -> 41 | I45: =' STAMP Summary'!AQ13 -> 28.5 | J45: =' STAMP Summary'!AR13 -> 0 | ... X45: =' STAMP Summary'!BF13 -> 0 | Z45: =CONCATENATE(DAY(B45),"-",TEXT(B45,"MMM")) -> 14-Mar | AA45: =' STAMP Summary'!BI13 -> 0.0038571429 | AB45: =' STAMP Summary'!BJ13 -> 0.003 | AC45: =' STAMP Summary'!BK13 -> 0.0022380952 | AD45: =' STAMP Summary'!BL13 -> 0.0053809524 | AE45: =' STAMP Summary'!BM13 -> 0.0011904762 | AF45: =' STAMP Summary'!BN13 -> 0.001952381 | AG45: =' STAMP Summary'!BO13 -> 0.0013571429 | AH45: =' STAMP Summary'!BP13 -> 0 | ... AV45: =' STAMP Summary'!CD13 -> 0 | AW45: =AVERAGE(AB45:AH45,AJ45,AL45:AM45,AO45,AQ45:AV45) -> 0.00088935574 | AX45: =_xlfn.PERCENTILE.INC((AB45:AH45,AJ45,AL45:AM45,AO45,AQ45:AV45),0.05) -> 0 | AY45: =_xlfn.PERCENTILE.INC((AB45:AH45,AJ45,AL45:AM45,AO45,AQ45:AV45),0.95) -> 0.0034761905 | BI45: =' STAMP Summary'!DE13 -> 41855 | BJ45: =' STAMP Summary'!DF13 -> 0 | BK45: =' STAMP Summary'!DG13 -> 0 | BL45: =' STAMP Summary'!DH13 -> 2 | BM45: =' STAMP Summary'!DI13 -> 0 | BN45: =' STAMP Summary'!DJ13 -> 0 | BO45: =' STAMP Summary'!DK13 -> 6 | BP45: =' STAMP Summary'!DL13 -> 0 | ... BW45: =' STAMP Summary'!DS13 -> 0 | BY45: =BI45 -> 41855 | BZ45: =$BK$34*CN45 -> 0.67684736 | CA45: =BK45/$BK$163 -> 0 | CB45: =BL45/BL$163 -> 0.00021142767 | CC45: =BM45/BM$163 -> 0 | CD45: =BN45/BN$163 -> 0 | CE45: =BO45/BO$163 -> 0.00098738097 | CF45: =BP45/BP$163 -> 0 | CG45: =BQ45/BQ$163 -> 0 | CH45: =BR45/BR$163 -> 0 | CI45: =BS45/BS$163 -> 0 | ... CM45: =BW45/BW$163 -> 0 | CN45: =AVERAGE(CA45:CE45) -> 0.00023976173 | CO45: =STDEV(CA45:CE45) -> 0.0004278418
B46: =' STAMP Summary'!A14 -> 0805 | C46: =' STAMP Summary'!AK14 -> 85 | D46: =' STAMP Summary'!AL14 -> 64 | E46: =' STAMP Summary'!AM14 -> 58 | F46: =' STAMP Summary'!AN14 -> 129 | G46: =' STAMP Summary'!AO14 -> 35 | H46: =' STAMP Summary'!AP14 -> 41 | I46: =' STAMP Summary'!AQ14 -> 32.5 | J46: =' STAMP Summary'!AR14 -> 3 | ... X46: =' STAMP Summary'!BF14 -> 0 | Z46: =CONCATENATE(DAY(B46),"-",TEXT(B46,"MMM")) -> 15-Mar | AA46: =' STAMP Summary'!BI14 -> 0.004047619 | AB46: =' STAMP Summary'!BJ14 -> 0.003047619 | AC46: =' STAMP Summary'!BK14 -> 0.0027619048 | AD46: =' STAMP Summary'!BL14 -> 0.0061428571 | AE46: =' STAMP Summary'!BM14 -> 0.0016666667 | AF46: =' STAMP Summary'!BN14 -> 0.001952381 | AG46: =' STAMP Summary'!BO14 -> 0.001547619 | AH46: =' STAMP Summary'!BP14 -> 0.00014285714 | ... AV46: =' STAMP Summary'!CD14 -> 0 | AW46: =AVERAGE(AB46:AH46,AJ46,AL46:AM46,AO46,AQ46:AV46) -> 0.0010154062 | AX46: =_xlfn.PERCENTILE.INC((AB46:AH46,AJ46,AL46:AM46,AO46,AQ46:AV46),0.05) -> 0 | AY46: =_xlfn.PERCENTILE.INC((AB46:AH46,AJ46,AL46:AM46,AO46,AQ46:AV46),0.95) -> 0.0036666667 | BI46: =' STAMP Summary'!DE14 -> 41856 | BJ46: =' STAMP Summary'!DF14 -> 0 | BK46: =' STAMP Summary'!DG14 -> 0 | BL46: =' STAMP Summary'!DH14 -> 2 | BM46: =' STAMP Summary'!DI14 -> 0 | BN46: =' STAMP Summary'!DJ14 -> 0 | BO46: =' STAMP Summary'!DK14 -> 6 | BP46: =' STAMP Summary'!DL14 -> 0 | ... BW46: =' STAMP Summary'!DS14 -> 0 | BY46: =BI46 -> 41856 | BZ46: =$BK$34*CN46 -> 0.67684736 | CA46: =BK46/$BK$163 -> 0 | CB46: =BL46/BL$163 -> 0.00021142767 | CC46: =BM46/BM$163 -> 0 | CD46: =BN46/BN$163 -> 0 | CE46: =BO46/BO$163 -> 0.00098738097 | CF46: =BP46/BP$163 -> 0 | CG46: =BQ46/BQ$163 -> 0 | CH46: =BR46/BR$163 -> 0 | CI46: =BS46/BS$163 -> 0 | ... CM46: =BW46/BW$163 -> 0 | CN46: =AVERAGE(CA46:CE46) -> 0.00023976173 | CO46: =STDEV(CA46:CE46) -> 0.0004278418
B47: =' STAMP Summary'!A15 -> 0806 | C47: =' STAMP Summary'!AK15 -> 97 | D47: =' STAMP Summary'!AL15 -> 66 | E47: =' STAMP Summary'!AM15 -> 70 | F47: =' STAMP Summary'!AN15 -> 155 | G47: =' STAMP Summary'!AO15 -> 36 | H47: =' STAMP Summary'!AP15 -> 47 | I47: =' STAMP Summary'!AQ15 -> 44.5 | J47: =' STAMP Summary'!AR15 -> 3 | ... X47: =' STAMP Summary'!BF15 -> 0 | Z47: =CONCATENATE(DAY(B47),"-",TEXT(B47,"MMM")) -> 16-Mar | AA47: =' STAMP Summary'!BI15 -> 0.0046190476 | AB47: =' STAMP Summary'!BJ15 -> 0.0031428571 | AC47: =' STAMP Summary'!BK15 -> 0.0033333333 | AD47: =' STAMP Summary'!BL15 -> 0.0073809524 | AE47: =' STAMP Summary'!BM15 -> 0.0017142857 | AF47: =' STAMP Summary'!BN15 -> 0.0022380952 | AG47: =' STAMP Summary'!BO15 -> 0.0021190476 | AH47: =' STAMP Summary'!BP15 -> 0.00014285714 | ... AV47: =' STAMP Summary'!CD15 -> 0 | AW47: =AVERAGE(AB47:AH47,AJ47,AL47:AM47,AO47,AQ47:AV47) -> 0.0011806723 | AX47: =_xlfn.PERCENTILE.INC((AB47:AH47,AJ47,AL47:AM47,AO47,AQ47:AV47),0.05) -> 0 | AY47: =_xlfn.PERCENTILE.INC((AB47:AH47,AJ47,AL47:AM47,AO47,AQ47:AV47),0.95) -> 0.0041428571 | BI47: =' STAMP Summary'!DE15 -> 41857 | BJ47: =' STAMP Summary'!DF15 -> 1 | BK47: =' STAMP Summary'!DG15 -> 0 | BL47: =' STAMP Summary'!DH15 -> 2 | BM47: =' STAMP Summary'!DI15 -> 0 | BN47: =' STAMP Summary'!DJ15 -> 0 | BO47: =' STAMP Summary'!DK15 -> 6 | BP47: =' STAMP Summary'!DL15 -> 0 | ... BW47: =' STAMP Summary'!DS15 -> 0 | BY47: =BI47 -> 41857 | BZ47: =$BK$34*CN47 -> 0.67684736 | CA47: =BK47/$BK$163 -> 0 | CB47: =BL47/BL$163 -> 0.00021142767 | CC47: =BM47/BM$163 -> 0 | CD47: =BN47/BN$163 -> 0 | CE47: =BO47/BO$163 -> 0.00098738097 | CF47: =BP47/BP$163 -> 0 | CG47: =BQ47/BQ$163 -> 0 | CH47: =BR47/BR$163 -> 0 | CI47: =BS47/BS$163 -> 0 | ... CM47: =BW47/BW$163 -> 0 | CN47: =AVERAGE(CA47:CE47) -> 0.00023976173 | CO47: =STDEV(CA47:CE47) -> 0.0004278418
B48: =' STAMP Summary'!A16 -> 0807 | C48: =' STAMP Summary'!AK16 -> 139 | D48: =' STAMP Summary'!AL16 -> 93 | E48: =' STAMP Summary'!AM16 -> 75 | F48: =' STAMP Summary'!AN16 -> 182 | G48: =' STAMP Summary'!AO16 -> 37 | H48: =' STAMP Summary'!AP16 -> 54 | I48: =' STAMP Summary'!AQ16 -> 57.5 | J48: =' STAMP Summary'!AR16 -> 3 | ... X48: =' STAMP Summary'!BF16 -> 0 | Z48: =CONCATENATE(DAY(B48),"-",TEXT(B48,"MMM")) -> 17-Mar | AA48: =' STAMP Summary'!BI16 -> 0.0066190476 | AB48: =' STAMP Summary'!BJ16 -> 0.0044285714 | AC48: =' STAMP Summary'!BK16 -> 0.0035714286 | AD48: =' STAMP Summary'!BL16 -> 0.0086666667 | AE48: =' STAMP Summary'!BM16 -> 0.0017619048 | AF48: =' STAMP Summary'!BN16 -> 0.0025714286 | AG48: =' STAMP Summary'!BO16 -> 0.0027380952 | AH48: =' STAMP Summary'!BP16 -> 0.00014285714 | ... AV48: =' STAMP Summary'!CD16 -> 0 | AW48: =AVERAGE(AB48:AH48,AJ48,AL48:AM48,AO48,AQ48:AV48) -> 0.0014047619 | AX48: =_xlfn.PERCENTILE.INC((AB48:AH48,AJ48,AL48:AM48,AO48,AQ48:AV48),0.05) -> 0 | AY48: =_xlfn.PERCENTILE.INC((AB48:AH48,AJ48,AL48:AM48,AO48,AQ48:AV48),0.95) -> 0.0052761905 | BI48: =' STAMP Summary'!DE16 -> 41858 | BJ48: =' STAMP Summary'!DF16 -> 1 | BK48: =' STAMP Summary'!DG16 -> 0 | BL48: =' STAMP Summary'!DH16 -> 3 | BM48: =' STAMP Summary'!DI16 -> 0 | BN48: =' STAMP Summary'!DJ16 -> 0 | BO48: =' STAMP Summary'!DK16 -> 6 | BP48: =' STAMP Summary'!DL16 -> 0 | ... BW48: =' STAMP Summary'!DS16 -> 0 | BY48: =BI48 -> 41858 | BZ48: =$BK$34*CN48 -> 0.73653339 | CA48: =BK48/$BK$163 -> 0 | CB48: =BL48/BL$163 -> 0.0003171415 | CC48: =BM48/BM$163 -> 0 | CD48: =BN48/BN$163 -> 0 | CE48: =BO48/BO$163 -> 0.00098738097 | CF48: =BP48/BP$163 -> 0 | CG48: =BQ48/BQ$163 -> 0 | CH48: =BR48/BR$163 -> 0 | CI48: =BS48/BS$163 -> 0 | ... CM48: =BW48/BW$163 -> 0 | CN48: =AVERAGE(CA48:CE48) -> 0.00026090449 | CO48: =STDEV(CA48:CE48) -> 0.00042870273
B49: =' STAMP Summary'!A17 -> 0808 | C49: =' STAMP Summary'!AK17 -> 203 | D49: =' STAMP Summary'!AL17 -> 119 | E49: =' STAMP Summary'!AM17 -> 89 | F49: =' STAMP Summary'!AN17 -> 199 | G49: =' STAMP Summary'!AO17 -> 37 | H49: =' STAMP Summary'!AP17 -> 61 | I49: =' STAMP Summary'!AQ17 -> 68.5 | J49: =' STAMP Summary'!AR17 -> 9 | ... X49: =' STAMP Summary'!BF17 -> 0 | Z49: =CONCATENATE(DAY(B49),"-",TEXT(B49,"MMM")) -> 18-Mar | AA49: =' STAMP Summary'!BI17 -> 0.0096666667 | AB49: =' STAMP Summary'!BJ17 -> 0.0056666667 | AC49: =' STAMP Summary'!BK17 -> 0.0042380952 | AD49: =' STAMP Summary'!BL17 -> 0.0094761905 | AE49: =' STAMP Summary'!BM17 -> 0.0017619048 | AF49: =' STAMP Summary'!BN17 -> 0.0029047619 | AG49: =' STAMP Summary'!BO17 -> 0.0032619048 | AH49: =' STAMP Summary'!BP17 -> 0.00042857143 | ... AV49: =' STAMP Summary'!CD17 -> 0 | AW49: =AVERAGE(AB49:AH49,AJ49,AL49:AM49,AO49,AQ49:AV49) -> 0.0016316527 | AX49: =_xlfn.PERCENTILE.INC((AB49:AH49,AJ49,AL49:AM49,AO49,AQ49:AV49),0.05) -> 0 | AY49: =_xlfn.PERCENTILE.INC((AB49:AH49,AJ49,AL49:AM49,AO49,AQ49:AV49),0.95) -> 0.0064285714 | BI49: =' STAMP Summary'!DE17 -> 41859 | BJ49: =' STAMP Summary'!DF17 -> 2 | BK49: =' STAMP Summary'!DG17 -> 0 | BL49: =' STAMP Summary'!DH17 -> 3 | BM49: =' STAMP Summary'!DI17 -> 0 | BN49: =' STAMP Summary'!DJ17 -> 1 | BO49: =' STAMP Summary'!DK17 -> 6 | BP49: =' STAMP Summary'!DL17 -> 0 | ... BW49: =' STAMP Summary'!DS17 -> 0 | BY49: =BI49 -> 41859 | BZ49: =$BK$34*CN49 -> 1.0492445 | CA49: =BK49/$BK$163 -> 0 | CB49: =BL49/BL$163 -> 0.0003171415 | CC49: =BM49/BM$163 -> 0 | CD49: =BN49/BN$163 -> 0.0005538632 | CE49: =BO49/BO$163 -> 0.00098738097 | CF49: =BP49/BP$163 -> 0 | CG49: =BQ49/BQ$163 -> 0 | CH49: =BR49/BR$163 -> 0 | CI49: =BS49/BS$163 -> 0 | ... CM49: =BW49/BW$163 -> 0 | CN49: =AVERAGE(CA49:CE49) -> 0.00037167713 | CO49: =STDEV(CA49:CE49) -> 0.00041579589
B50: =' STAMP Summary'!A18 -> 0809 | C50: =' STAMP Summary'!AK18 -> 230 | D50: =' STAMP Summary'!AL18 -> 170 | E50: =' STAMP Summary'!AM18 -> 100 | F50: =' STAMP Summary'!AN18 -> 217 | G50: =' STAMP Summary'!AO18 -> 37 | H50: =' STAMP Summary'!AP18 -> 64 | I50: =' STAMP Summary'!AQ18 -> 76.5 | J50: =' STAMP Summary'!AR18 -> 12 | ... X50: =' STAMP Summary'!BF18 -> 0 | Z50: =CONCATENATE(DAY(B50),"-",TEXT(B50,"MMM")) -> 19-Mar | AA50: =' STAMP Summary'!BI18 -> 0.010952381 | AB50: =' STAMP Summary'!BJ18 -> 0.0080952381 | AC50: =' STAMP Summary'!BK18 -> 0.0047619048 | AD50: =' STAMP Summary'!BL18 -> 0.010333333 | AE50: =' STAMP Summary'!BM18 -> 0.0017619048 | AF50: =' STAMP Summary'!BN18 -> 0.003047619 | AG50: =' STAMP Summary'!BO18 -> 0.0036428571 | AH50: =' STAMP Summary'!BP18 -> 0.00057142857 | ... AV50: =' STAMP Summary'!CD18 -> 0 | AW50: =AVERAGE(AB50:AH50,AJ50,AL50:AM50,AO50,AQ50:AV50) -> 0.001894958 | AX50: =_xlfn.PERCENTILE.INC((AB50:AH50,AJ50,AL50:AM50,AO50,AQ50:AV50),0.05) -> 0 | AY50: =_xlfn.PERCENTILE.INC((AB50:AH50,AJ50,AL50:AM50,AO50,AQ50:AV50),0.95) -> 0.0085428571 | BI50: =' STAMP Summary'!DE18 -> 41860 | BJ50: =' STAMP Summary'!DF18 -> 2 | BK50: =' STAMP Summary'!DG18 -> 0 | BL50: =' STAMP Summary'!DH18 -> 3 | BM50: =' STAMP Summary'!DI18 -> 1 | BN50: =' STAMP Summary'!DJ18 -> 1 | BO50: =' STAMP Summary'!DK18 -> 6 | BP50: =' STAMP Summary'!DL18 -> 0 | ... BW50: =' STAMP Summary'!DS18 -> 0 | BY50: =BI50 -> 41860 | BZ50: =$BK$34*CN50 -> 1.1577484 | CA50: =BK50/$BK$163 -> 0 | CB50: =BL50/BL$163 -> 0.0003171415 | CC50: =BM50/BM$163 -> 0.00019217834 | CD50: =BN50/BN$163 -> 0.0005538632 | CE50: =BO50/BO$163 -> 0.00098738097 | CF50: =BP50/BP$163 -> 0 | CG50: =BQ50/BQ$163 -> 0 | CH50: =BR50/BR$163 -> 0 | CI50: =BS50/BS$163 -> 0 | ... CM50: =BW50/BW$163 -> 0 | CN50: =AVERAGE(CA50:CE50) -> 0.0004101128 | CO50: =STDEV(CA50:CE50) -> 0.0003802086
B51: =' STAMP Summary'!A19 -> 0810 | C51: =' STAMP Summary'!AK19 -> 291 | D51: =' STAMP Summary'!AL19 -> 193 | E51: =' STAMP Summary'!AM19 -> 144 | F51: =' STAMP Summary'!AN19 -> 269 | G51: =' STAMP Summary'!AO19 -> 39 | H51: =' STAMP Summary'!AP19 -> 67 | I51: =' STAMP Summary'!AQ19 -> 85 | J51: =' STAMP Summary'!AR19 -> 15 | ... X51: =' STAMP Summary'!BF19 -> 0 | Z51: =CONCATENATE(DAY(B51),"-",TEXT(B51,"MMM")) -> 20-Mar | AA51: =' STAMP Summary'!BI19 -> 0.013857143 | AB51: =' STAMP Summary'!BJ19 -> 0.0091904762 | AC51: =' STAMP Summary'!BK19 -> 0.0068571429 | AD51: =' STAMP Summary'!BL19 -> 0.012809524 | AE51: =' STAMP Summary'!BM19 -> 0.0018571429 | AF51: =' STAMP Summary'!BN19 -> 0.0031904762 | AG51: =' STAMP Summary'!BO19 -> 0.004047619 | AH51: =' STAMP Summary'!BP19 -> 0.00071428571 | ... AV51: =' STAMP Summary'!CD19 -> 0 | AW51: =AVERAGE(AB51:AH51,AJ51,AL51:AM51,AO51,AQ51:AV51) -> 0.0022745098 | AX51: =_xlfn.PERCENTILE.INC((AB51:AH51,AJ51,AL51:AM51,AO51,AQ51:AV51),0.05) -> 0 | AY51: =_xlfn.PERCENTILE.INC((AB51:AH51,AJ51,AL51:AM51,AO51,AQ51:AV51),0.95) -> 0.0099142857 | BI51: =' STAMP Summary'!DE19 -> 41861 | BJ51: =' STAMP Summary'!DF19 -> 2 | BK51: =' STAMP Summary'!DG19 -> 0 | BL51: =' STAMP Summary'!DH19 -> 3 | BM51: =' STAMP Summary'!DI19 -> 2 | BN51: =' STAMP Summary'!DJ19 -> 1 | BO51: =' STAMP Summary'!DK19 -> 7 | BP51: =' STAMP Summary'!DL19 -> 0 | ... BW51: =' STAMP Summary'!DS19 -> 0 | BY51: =BI51 -> 41861 | BZ51: =$BK$34*CN51 -> 1.3591649 | CA51: =BK51/$BK$163 -> 0 | CB51: =BL51/BL$163 -> 0.0003171415 | CC51: =BM51/BM$163 -> 0.00038435668 | CD51: =BN51/BN$163 -> 0.0005538632 | CE51: =BO51/BO$163 -> 0.0011519445 | CF51: =BP51/BP$163 -> 0 | CG51: =BQ51/BQ$163 -> 0 | CH51: =BR51/BR$163 -> 0 | CI51: =BS51/BS$163 -> 0 | ... CM51: =BW51/BW$163 -> 0 | CN51: =AVERAGE(CA51:CE51) -> 0.00048146117 | CO51: =STDEV(CA51:CE51) -> 0.00042515438
